#VRML_SIM R2025a utf8

EXTERNPROTO "https://raw.githubusercontent.com/cyberbotics/webots/R2025a/projects/objects/backgrounds/protos/TexturedBackground.proto"
EXTERNPROTO "https://raw.githubusercontent.com/cyberbotics/webots/R2025a/projects/objects/backgrounds/protos/TexturedBackgroundLight.proto"
EXTERNPROTO "https://raw.githubusercontent.com/cyberbotics/webots/R2025a/projects/objects/floors/protos/RectangleArena.proto"
EXTERNPROTO "https://raw.githubusercontent.com/cyberbotics/webots/R2025a/projects/appearances/protos/Parquetry.proto"
EXTERNPROTO "https://raw.githubusercontent.com/cyberbotics/webots/R2025a/projects/objects/garden/protos/DogHouse.proto"
EXTERNPROTO "https://raw.githubusercontent.com/cyberbotics/webots/R2025a/projects/objects/garden/protos/Gnome.proto"

WorldInfo {
}
Viewpoint {
  orientation -0.2838081077291116 -0.004117548733288604 0.9588722562362776 3.4959138970384047
  position 3.466743392086754 2.85761694953784 2.9882760913357016
  followType "Mounted Shot"
}
TexturedBackground {
}
TexturedBackgroundLight {
}
RectangleArena {
  floorSize 10 10
  floorAppearance Parquetry {
  }
  wallHeight 1
}
Gnome {
  translation -3.66 -3.64 0
  name "gnome(5)"
}
Gnome {
  translation -0.44 1.14 0
  name "gnome(6)"
}
Gnome {
  translation 3.11 1.28 0
  name "gnome(7)"
}
Gnome {
  translation 2.74 -2.28 0
  name "gnome(8)"
}
Gnome {
  translation -2.25 -2.09 0
  name "gnome(9)"
}
Gnome {
  translation 2.27 0 0
  name "gnome(1)"
}
Gnome {
  translation -1.4 0 0
  name "gnome(2)"
}
DogHouse {
  translation -4.01 4.37 0
}
Gnome {
  translation 0.69 0 0
}
Gnome {
  translation 0.69 -2.7 0
  name "gnome(3)"
}
Gnome {
  translation 0.69 2.08 0
  name "gnome(4)"
}
Robot {
  translation -1.13603 1.96887 0.489013
  rotation 0.9533450849023621 0.07152940637021753 -0.29328602611926863 -0.025955307179586384
  children [
    Camera {
      translation 0 0.3 0.3
      width 640
      height 640
    }
    DEF Body Pose {
      translation 0 0 0.1
      children [
        Shape {
          appearance PBRAppearance {
            baseColorMap ImageTexture {
              url [
                "https://imgs.search.brave.com/0YGtxc25S4zUGUYkWpcBq0qB9CeOH0b-VXL8z7GN394/rs:fit:860:0:0:0/g:ce/aHR0cHM6Ly93d3cu/c3VwZXJtYW5tb3Zp/ZS5jb20vYXNzZXRz/L2ltYWdlcy9pcGFk/YmFubmVycG9ydHJh/aXQuanBn"
              ]
            }
          }
          geometry Box {
            size 0.6 0.6 0.6
          }
        }
      ]
    }
    HingeJoint {
      jointParameters HingeJointParameters {
        position -13.161867971257065
        anchor 0.31 0 -0.2
      }
      device [
        RotationalMotor {
          name "motor1"
        }
        PositionSensor {
          name "motor1_sensor"
        }
      ]
      endPoint Solid {
        translation 0.31005913656409956 -0.0019475347623531692 -0.17985115724704234
        rotation -0.28183890925950356 0.9172630749064106 -0.2814165607078771 1.6560162179784321
        children [
          DEF wheel Shape {
            appearance PBRAppearance {
            }
            geometry Cylinder {
              height 0.1
              radius 0.15
            }
          }
        ]
        boundingObject USE wheel
        physics DEF wheelPhysics Physics {
        }
      }
    }
    HingeJoint {
      jointParameters HingeJointParameters {
        position -8.535676251008242
        anchor -0.35 0 -0.2
      }
      device [
        PositionSensor {
          name "motor2_sensor"
        }
        RotationalMotor {
          name "motor2"
        }
      ]
      endPoint Solid {
        translation -0.3500181716670432 0.0002301884472280004 -0.18143677280563084
        rotation -0.670420225760463 0.3189942170856982 -0.669910001684683 2.5231400597114306
        children [
          USE wheel
        ]
        name "solid(1)"
        boundingObject USE wheel
        physics USE wheelPhysics
      }
    }
  ]
  boundingObject USE Body
  physics Physics {
  }
  controller "controladorRobot"
}
Robot {
  children [
    Transform {
      translation 0 0 1
      children [
        Shape {
          appearance PBRAppearance {
            baseColor 0 0 1
          }
          geometry Cylinder {
            height 0.3
            radius 0.3
          }
        }
      ]
    }
  ]
  name "robot(1)"
}
